I synced the node and opened the wallet with Putty. Localhost Port 2000.
Fist I used the command Wallet. This worked fine and displayed 0 balance. Then I typed recoverfromhexseed so I could make sure I could recover my wallet. Then Putty force closed and this message appeared within the Node printout
`4cec30d4ed899253c1d2860b0975899b2fc6e609c255d2bf413a9290c48ba8d2
Unhandled Error
Traceback (most recent call last):
File "C:\Python27\lib\site-packages\twisted\python\log.py", line 103, in callWithLogger
return callWithContext({"system": lp}, func, *args, **kw)
File "C:\Python27\lib\site-packages\twisted\python\log.py", line 86, in callWithContext
return context.call({ILogContext: newCtx}, func, *args, **kw)
File "C:\Python27\lib\site-packages\twisted\python\context.py", line 122, in callWithContext
return self.currentContext().callWithContext(ctx, func, *args, **kw)
File "C:\Python27\lib\site-packages\twisted\python\context.py", line 85, in callWithContext
return func(*args,**kw)
---  ---
File "C:\Python27\lib\site-packages\twisted\internet\selectreactor.py", line 149, in _doReadOrWrite
why = getattr(selectable, method)()
File "C:\Python27\lib\site-packages\twisted\internet\tcp.py", line 208, in doRead
return self._dataReceived(data)
File "C:\Python27\lib\site-packages\twisted\internet\tcp.py", line 214, in _dataReceived
rval = self.protocol.dataReceived(data)
File "node.py", line 1354, in dataReceived
File "node.py", line 1269, in parse_cmd
exceptions.IndexError: list index out of range
`
