my code originally did not have this kind of error, it occured today suddenly.
Traceback (most recent call last):
File "/home/kim/Documents/qc/pyquil-master/pyquil/api/_base_connection.py", line 100, in parse_error
body = res.json()
File "/usr/lib/python3.4/site-packages/requests/models.py", line 819, in json
return json.loads(self.text, **kwargs)
File "/usr/lib64/python3.4/site-packages/simplejson/init.py", line 516, in loads
return _default_decoder.decode(s)
File "/usr/lib64/python3.4/site-packages/simplejson/decoder.py", line 370, in decode
obj, end = self.raw_decode(s)
File "/usr/lib64/python3.4/site-packages/simplejson/decoder.py", line 400, in raw_decode
return self.scan_once(s, idx=_w(s, idx).end())
simplejson.scanner.JSONDecodeError: Expecting value: line 1 column 1 (char 0)
During handling of the above exception, another exception occurred:
Traceback (most recent call last):
File "qle.py", line 94, in 
main()
File "qle.py", line 91, in main
print(get_density_matrix(Sys,states,dim,w))
File "qle.py", line 58, in get_density_matrix
coeff[j][i] += qvm.wavefunction(Sys[i]).amplitudes[j]
File "/home/kim/Documents/qc/pyquil-master/pyquil/api/qvm.py", line 284, in wavefunction
response = post_json(self.session, self.sync_endpoint + "/qvm", payload)
File "/home/kim/Documents/qc/pyquil-master/pyquil/api/_base_connection.py", line 88, in post_json
raise parse_error(res)
File "/home/kim/Documents/qc/pyquil-master/pyquil/api/_base_connection.py", line 102, in parse_error
raise UnknownApiError(res.text)
pyquil.api.errors.UnknownApiError: 
The server has failed to return a proper response. Please describe the problem
and copy the above message into a GitHub issue at:
https://github.com/rigetticomputing/pyquil/issues
Could you please post the code you are trying to run?
Hi @rodak414, thanks for submitting. This is a known issue that we are working to resolve- if you try running your program again after encountering this error message, it should still work. We will update you as we resolve this issue!
